[
  {
    "DefinitionID": "oval:com.ubuntu.bionic:def:201999480000000",
    "Title": "CVE-2019-9948 on Ubuntu 18.04 LTS (bionic) - medium.",
    "Description": "urllib in Python 2.x through 2.7.16 supports the local_file: scheme, which makes it easier for remote attackers to bypass protection mechanisms that blacklist file: URIs, as demonstrated by triggering a urllib.urlopen('local_file:///etc/passwd') call.",
    "Advisory": {
      "Severity": "Medium",
      "Cves": [
        {
          "CveID": "CVE-2019-9948",
          "Cvss2": "",
          "Cvss3": "",
          "Cwe": "",
          "Impact": "",
          "Href": "https://cve.mitre.org/cgi-bin/cvename.cgi?name=CVE-2019-9948",
          "Public": ""
        }
      ],
      "Bugzillas": [],
      "AffectedCPEList": [],
      "Issued": "1000-01-01T00:00:00Z",
      "Updated": "1000-01-01T00:00:00Z"
    },
    "Debian": null,
    "AffectedPacks": [
      {
        "Name": "python2.7",
        "Version": "2.7.15-4ubuntu4~18.04.1",
        "Arch": "",
        "NotFixedYet": false,
        "ModularityLabel": ""
      },
      {
        "Name": "python3.6",
        "Version": "3.6.8-1~18.04.2",
        "Arch": "",
        "NotFixedYet": false,
        "ModularityLabel": ""
      },
      {
        "Name": "python3.7",
        "Version": "",
        "Arch": "",
        "NotFixedYet": true,
        "ModularityLabel": ""
      }
    ],
    "References": [
      {
        "Source": "CVE",
        "RefID": "CVE-2019-9948",
        "RefURL": "https://cve.mitre.org/cgi-bin/cvename.cgi?name=CVE-2019-9948"
      },
      {
        "Source": "Ref",
        "RefID": "",
        "RefURL": "http://people.canonical.com/~ubuntu-security/cve/2019/CVE-2019-9948.html"
      },
      {
        "Source": "Ref",
        "RefID": "",
        "RefURL": "https://github.com/python/cpython/pull/11842"
      },
      {
        "Source": "Ref",
        "RefID": "",
        "RefURL": "https://ubuntu.com/security/notices/USN-4127-1"
      },
      {
        "Source": "Ref",
        "RefID": "",
        "RefURL": "https://ubuntu.com/security/notices/USN-4127-2"
      },
      {
        "Source": "Bug",
        "RefID": "",
        "RefURL": "https://bugs.python.org/issue35907"
      }
    ]
  }
]
