[
  {
    "DefinitionID": "oval:org.debian:def:120717566219174507924640510876111322261",
    "Title": "CVE-2021-3733 python3.9",
    "Description": "",
    "Advisory": {
      "Severity": "",
      "Cves": [
        {
          "CveID": "CVE-2021-3733",
          "Cvss2": "",
          "Cvss3": "",
          "Cwe": "",
          "Impact": "",
          "Href": "https://cve.mitre.org/cgi-bin/cvename.cgi?name=CVE-2021-3733",
          "Public": ""
        }
      ],
      "Bugzillas": [],
      "AffectedCPEList": [],
      "Issued": "1000-01-01T00:00:00Z",
      "Updated": "1000-01-01T00:00:00Z"
    },
    "Debian": {
      "MoreInfo": "",
      "Date": "1000-01-01T00:00:00Z"
    },
    "AffectedPacks": [],
    "References": [
      {
        "Source": "CVE",
        "RefID": "CVE-2021-3733",
        "RefURL": "https://cve.mitre.org/cgi-bin/cvename.cgi?name=CVE-2021-3733"
      }
    ]
  }
]
