[
  {
    "DefinitionID": "oval:com.ubuntu.xenial:def:2021324920000000",
    "Title": "CVE-2021-32492 on Ubuntu 16.04 LTS (xenial) - low.",
    "Description": "A flaw was found in djvulibre-3.5.28 and earlier. An out of bounds read in function DJVU::DataPool::has_data() via crafted djvu file may lead to application crash and other consequences.",
    "Advisory": {
      "Severity": "Low",
      "Cves": [
        {
          "CveID": "CVE-2021-32492",
          "Cvss2": "",
          "Cvss3": "",
          "Cwe": "",
          "Impact": "",
          "Href": "https://cve.mitre.org/cgi-bin/cvename.cgi?name=CVE-2021-32492",
          "Public": ""
        }
      ],
      "Bugzillas": [],
      "AffectedCPEList": [],
      "Issued": "1000-01-01T00:00:00Z",
      "Updated": "1000-01-01T00:00:00Z"
    },
    "Debian": null,
    "AffectedPacks": [],
    "References": [
      {
        "Source": "CVE",
        "RefID": "CVE-2021-32492",
        "RefURL": "https://cve.mitre.org/cgi-bin/cvename.cgi?name=CVE-2021-32492"
      },
      {
        "Source": "Ref",
        "RefID": "",
        "RefURL": "http://people.canonical.com/~ubuntu-security/cve/2021/CVE-2021-32492.html"
      },
      {
        "Source": "Ref",
        "RefID": "",
        "RefURL": "https://ubuntu.com/security/notices/USN-4957-1"
      },
      {
        "Source": "Ref",
        "RefID": "",
        "RefURL": "https://ubuntu.com/security/notices/USN-4957-2"
      },
      {
        "Source": "Bug",
        "RefID": "",
        "RefURL": "https://bugzilla.redhat.com/show_bug.cgi?id=1943410"
      },
      {
        "Source": "Bug",
        "RefID": "",
        "RefURL": "https://bugzilla.redhat.com/show_bug.cgi?id=1943686"
      }
    ]
  }
]
